[2023-08-24 09:56:42,826: INFO/MainProcess] Connected to redis://redis:6379//
[2023-08-24 09:56:42,872: INFO/MainProcess] mingle: searching for neighbors
[2023-08-24 09:56:44,063: INFO/MainProcess] mingle: all alone
[2023-08-24 09:56:44,234: INFO/MainProcess] pidbox: Connected to redis://redis:6379//.
[2023-08-24 09:56:44,237: WARNING/MainProcess] /root/.local/lib/python3.6/site-packages/celery/fixups/django.py:206: UserWarning: Using settings.DEBUG leads to a memory
            leak, never use this setting in production environments!
  leak, never use this setting in production environments!''')
[2023-08-24 09:56:44,237: INFO/MainProcess] celery@b30347d436de ready.
[2023-08-24 09:58:16,873: WARNING/MainProcess] consumer: Connection to broker lost. Trying to re-establish the connection...
Traceback (most recent call last):
  File "/root/.local/lib/python3.6/site-packages/celery/worker/consumer/consumer.py", line 318, in start
    blueprint.start(self)
  File "/root/.local/lib/python3.6/site-packages/celery/bootsteps.py", line 119, in start
    step.start(parent)
  File "/root/.local/lib/python3.6/site-packages/celery/worker/consumer/consumer.py", line 599, in start
    c.loop(*c.loop_args())
  File "/root/.local/lib/python3.6/site-packages/celery/worker/loops.py", line 113, in synloop
    connection.drain_events(timeout=2.0)
  File "/root/.local/lib/python3.6/site-packages/kombu/connection.py", line 324, in drain_events
    return self.transport.drain_events(self.connection, **kwargs)
  File "/root/.local/lib/python3.6/site-packages/kombu/transport/virtual/base.py", line 963, in drain_events
    get(self._deliver, timeout=timeout)
  File "/root/.local/lib/python3.6/site-packages/kombu/transport/redis.py", line 376, in get
    ret = self.handle_event(fileno, event)
  File "/root/.local/lib/python3.6/site-packages/kombu/transport/redis.py", line 358, in handle_event
    return self.on_readable(fileno), self
  File "/root/.local/lib/python3.6/site-packages/kombu/transport/redis.py", line 354, in on_readable
    chan.handlers[type]()
  File "/root/.local/lib/python3.6/site-packages/kombu/transport/redis.py", line 688, in _receive
    ret.append(self._receive_one(c))
  File "/root/.local/lib/python3.6/site-packages/kombu/transport/redis.py", line 698, in _receive_one
    response = c.parse_response()
  File "/root/.local/lib/python3.6/site-packages/redis/client.py", line 3505, in parse_response
    response = self._execute(conn, conn.read_response)
  File "/root/.local/lib/python3.6/site-packages/redis/client.py", line 3479, in _execute
    return command(*args, **kwargs)
  File "/root/.local/lib/python3.6/site-packages/redis/connection.py", line 739, in read_response
    response = self._parser.read_response()
  File "/root/.local/lib/python3.6/site-packages/redis/connection.py", line 324, in read_response
    raw = self._buffer.readline()
  File "/root/.local/lib/python3.6/site-packages/redis/connection.py", line 256, in readline
    self._read_from_socket()
  File "/root/.local/lib/python3.6/site-packages/redis/connection.py", line 201, in _read_from_socket
    raise ConnectionError(SERVER_CLOSED_CONNECTION_ERROR)
redis.exceptions.ConnectionError: Connection closed by server.
[2023-08-24 09:58:17,933: WARNING/MainProcess] Traceback (most recent call last):
[2023-08-24 09:58:17,934: WARNING/MainProcess] File "/root/.local/lib/python3.6/site-packages/eventlet/hubs/poll.py", line 111, in wait
    listener.cb(fileno)
[2023-08-24 09:58:17,934: WARNING/MainProcess] File "/root/.local/lib/python3.6/site-packages/celery/worker/pidbox.py", line 120, in loop
    connection.drain_events(timeout=1.0)
[2023-08-24 09:58:17,934: WARNING/MainProcess] File "/root/.local/lib/python3.6/site-packages/kombu/connection.py", line 324, in drain_events
    return self.transport.drain_events(self.connection, **kwargs)
[2023-08-24 09:58:17,934: WARNING/MainProcess] File "/root/.local/lib/python3.6/site-packages/kombu/transport/virtual/base.py", line 963, in drain_events
    get(self._deliver, timeout=timeout)
[2023-08-24 09:58:17,934: WARNING/MainProcess] File "/root/.local/lib/python3.6/site-packages/kombu/transport/redis.py", line 376, in get
    ret = self.handle_event(fileno, event)
[2023-08-24 09:58:17,934: WARNING/MainProcess] File "/root/.local/lib/python3.6/site-packages/kombu/transport/redis.py", line 358, in handle_event
    return self.on_readable(fileno), self
[2023-08-24 09:58:17,934: WARNING/MainProcess] File "/root/.local/lib/python3.6/site-packages/kombu/transport/redis.py", line 354, in on_readable
    chan.handlers[type]()
[2023-08-24 09:58:17,934: WARNING/MainProcess] File "/root/.local/lib/python3.6/site-packages/kombu/transport/redis.py", line 688, in _receive
    ret.append(self._receive_one(c))
[2023-08-24 09:58:17,934: WARNING/MainProcess] File "/root/.local/lib/python3.6/site-packages/kombu/transport/redis.py", line 698, in _receive_one
    response = c.parse_response()
[2023-08-24 09:58:17,934: WARNING/MainProcess] File "/root/.local/lib/python3.6/site-packages/redis/client.py", line 3505, in parse_response
    response = self._execute(conn, conn.read_response)
[2023-08-24 09:58:17,934: WARNING/MainProcess] File "/root/.local/lib/python3.6/site-packages/redis/client.py", line 3479, in _execute
    return command(*args, **kwargs)
[2023-08-24 09:58:17,934: WARNING/MainProcess] File "/root/.local/lib/python3.6/site-packages/redis/connection.py", line 739, in read_response
    response = self._parser.read_response()
[2023-08-24 09:58:17,934: WARNING/MainProcess] File "/root/.local/lib/python3.6/site-packages/redis/connection.py", line 324, in read_response
    raw = self._buffer.readline()
[2023-08-24 09:58:17,934: WARNING/MainProcess] File "/root/.local/lib/python3.6/site-packages/redis/connection.py", line 256, in readline
    self._read_from_socket()
[2023-08-24 09:58:17,934: WARNING/MainProcess] File "/root/.local/lib/python3.6/site-packages/redis/connection.py", line 201, in _read_from_socket
    raise ConnectionError(SERVER_CLOSED_CONNECTION_ERROR)
[2023-08-24 09:58:17,934: WARNING/MainProcess] redis.exceptions.ConnectionError: Connection closed by server.
[2023-08-24 09:58:17,934: WARNING/MainProcess] Removing descriptor: 10
[2023-08-24 09:58:18,038: INFO/MainProcess] Connected to redis://redis:6379//
[2023-08-24 09:58:18,087: INFO/MainProcess] mingle: searching for neighbors
[2023-08-24 09:58:19,205: INFO/MainProcess] mingle: all alone
[2023-08-24 09:58:19,411: INFO/MainProcess] pidbox: Connected to redis://redis:6379//.
[2023-08-24 09:58:28,520: INFO/MainProcess] Connected to redis://redis:6379//
[2023-08-24 09:58:28,636: INFO/MainProcess] mingle: searching for neighbors
[2023-08-24 09:58:29,825: INFO/MainProcess] mingle: all alone
[2023-08-24 09:58:29,875: INFO/MainProcess] pidbox: Connected to redis://redis:6379//.
[2023-08-24 09:58:29,926: WARNING/MainProcess] /root/.local/lib/python3.6/site-packages/celery/fixups/django.py:206: UserWarning: Using settings.DEBUG leads to a memory
            leak, never use this setting in production environments!
  leak, never use this setting in production environments!''')
[2023-08-24 09:58:29,926: INFO/MainProcess] celery@b30347d436de ready.
